<mujoco model="sirius_wheel">
    <compiler angle="radian" meshdir="assets/" autolimits="true"/>
    <option cone="elliptic" impratio="100" integrator="implicitfast" timestep="0.001"/>
    <visual>
        <global ellipsoidinertia="true"/>
    </visual>

    <default>
        <default class="sirius_wheel">
            <geom condim="6" solimp="0.5 0.95 0.001 0.5 2"/>
            <site group="5"/>
            <default class="abad">
                <motor ctrlrange="-40 40" forcerange="-40 40"/>
            </default>
            <default class="hip">
                <motor ctrlrange="-40 40" forcerange="-40 40"/>
            </default>
            <default class="knee">
                <motor ctrlrange="-100 100" forcerange="-100 100"/>
            </default>
            <default class="wheel">
                <motor ctrlrange="-40 40" forcerange="-40 40"/>
            </default>
            <default class="visual">
                <geom type="mesh" contype="0" conaffinity="0" group="2"/>
            </default>
            <default class="collision">
                <geom group="3"/>
            </default>
        </default>
    </default>

    <asset>
        <mesh name="base_link" file="base_link.STL"/>
        <mesh name="LF_ABAD_Link" file="LF_ABAD_Link.STL"/>
        <mesh name="LF_THIGH_Link" file="LF_THIGH_Link.STL"/>
        <mesh name="LF_SHANK_Link" file="LF_SHANK_Link.STL"/>
        <mesh name="LF_FOOT_Link" file="LF_FOOT_Link.STL"/>
        <mesh name="RF_ABAD_Link" file="RF_ABAD_Link.STL"/>
        <mesh name="RF_THIGH_Link" file="RF_THIGH_Link.STL"/>
        <mesh name="RF_SHANK_Link" file="RF_SHANK_Link.STL"/>
        <mesh name="RF_FOOT_Link" file="RF_FOOT_Link.STL"/>
        <mesh name="LH_ABAD_Link" file="LH_ABAD_Link.STL"/>
        <mesh name="LH_THIGH_Link" file="LH_THIGH_Link.STL"/>
        <mesh name="LH_SHANK_Link" file="LH_SHANK_Link.STL"/>
        <mesh name="LH_FOOT_Link" file="LH_FOOT_Link.STL"/>
        <mesh name="RH_ABAD_Link" file="RH_ABAD_Link.STL"/>
        <mesh name="RH_THIGH_Link" file="RH_THIGH_Link.STL"/>
        <mesh name="RH_SHANK_Link" file="RH_SHANK_Link.STL"/>
        <mesh name="RH_FOOT_Link" file="RH_FOOT_Link.STL"/>
        <material name="grey" rgba="0.2 0.2 0.2 1.0"/>
    </asset>

    <worldbody>
        <body name="trunk" pos="0 0 1.0" childclass="sirius_wheel">
            <camera name="tracking" mode="trackcom" pos="0 -1 0.8" xyaxes="1 0 0 0 1 1"/>
            <inertial pos="0.00771202 -2.38069e-06 0.00294617" quat="1.00163e-05 0.70184 1.85912e-05 0.712335" mass="21.5552" diaginertia="0.962219 0.890231 0.122532"/>
            <joint name="floating_base_joint" type="free" limited="false" actuatorfrclimited="false"/>
            <geom class="visual" type="mesh" density="0" rgba="0.698039 0.698039 0.698039 1" mesh="base_link"/>
            <geom class="collision" size="0.2625 0.125 0.057" type="box" rgba="0.698039 0.698039 0.698039 1"/>
            <geom class="collision" size="0.0525 0.105 0.06" pos="0.418 0 0" type="box" rgba="0.698039 0.698039 0.698039 1"/>
            <geom class="collision" size="0.045 0.105 0.06" pos="-0.4105 0 0" type="box" rgba="0.698039 0.698039 0.698039 1"/>
            <site name="imu" pos="0.0043 -0.02 0.0414"/>

            <body name="RF_abad_link" pos="0.3154 -0.05 0">

                <inertial pos="-2.01943e-06 -0.0119999 -3.7868e-06" quat="0.000596564 0.707104 0.000520837 0.707109" mass="0.778648" diaginertia="0.00121131 0.000960297 0.000879709"/>
                <joint name="RF_HAA" pos="0 0 0" axis="1 0 0" range="-1.57 1.57" actuatorfrcrange="-40 40"/>
                <geom class="visual" type="mesh" density="0" rgba="0.698039 0.698039 0.698039 1" mesh="RF_ABAD_Link"/>
                <geom class="collision" size="0.04 0.0325" quat="0.707107 0 0.707107 0" type="cylinder" rgba="0.698039 0.698039 0.698039 1"/>
                <body name="RF_thigh_link" pos="0 -0.1388 0">
                    <inertial pos="-0.00412079 0.0352397 -0.029084" quat="0.469884 -0.00183031 0.11521 0.875176" mass="2.10685" diaginertia="0.0136982 0.0135394 0.00268877"/>
                    <joint name="RF_HFE" pos="0 0 0" axis="0 1 0" range="-1.04 4.18" actuatorfrcrange="-40 40"/>
                    <geom class="visual" type="mesh" density="0" rgba="0.698039 0.698039 0.698039 1" mesh="RF_THIGH_Link"/>
<!--                    <geom class="collision" type="mesh" rgba="0.698039 0.698039 0.698039 1" mesh="RF_THIGH_Link"/>-->
                    <geom class="collision" size="0.048 0.0175" pos="0 0.048 0" quat="0.707107 0.707107 0 0" type="cylinder" rgba="0.698039 0.698039 0.698039 1"/>
                    <geom class="collision" size="0.062 0.025" quat="0.707107 0.707107 0 0" type="cylinder" rgba="0.698039 0.698039 0.698039 1"/>
                    <geom class="collision" size="0.075 0.025 0.025" pos="-0.03 0 -0.15" quat="0.707107 0 0.707107 0" type="box" rgba="0.698039 0.698039 0.698039 1"/>
                    <body name="RF_shank_link" pos="0 0 -0.272">
                        <inertial pos="0.00691056 -0.0384575 -0.310502" quat="0.525419 -0.0225167 0.0943718 0.845294" mass="1.26478" diaginertia="0.0162682 0.0158354 0.00130658"/>
                        <joint name="RF_KNEE" pos="0 0 0" axis="0 1 0" range="-2.69 -0.68" actuatorfrcrange="-100 100"/>
                        <geom class="visual" type="mesh" density="0" rgba="0.698039 0.698039 0.698039 1" mesh="RF_SHANK_Link"/>
                        <geom class="collision" size="0.09 0.0125 0.0125" pos="0.035 0 -0.13" quat="0.764842 0 0.644218 0" type="box" rgba="0.698039 0.698039 0.698039 1"/>
                        <geom class="collision" size="0.045 0.016 0.0175" pos="0.03 0 -0.27" quat="0.581683 0 0.813416 0" type="box" rgba="0.698039 0.698039 0.698039 1"/>
<!--                        <geom class="collision" type="mesh" rgba="0.698039 0.698039 0.698039 1" mesh="RF_SHANK_Link"/>-->
                        <body name="RF_FOOT_link" pos="0 -0.0889282 -0.365367" quat="1 3.81916e-05 -5.98329e-10 -1.56665e-05">
                            <inertial pos="-4.11892e-09 0.016568 -6.73453e-10" quat="0.5 0.5 0.5 0.5" mass="0.750197" diaginertia="0.00508244 0.00268749 0.00268749"/>
                            <joint name="RF_WHEEL" pos="0 0 0" axis="0 1 0" range="-17453.3 17453.3" actuatorfrcrange="-40 40"/>
                            <geom class="visual" type="mesh" density="0" material="grey" mesh="RF_FOOT_Link"/>
                            <geom class="collision" type="cylinder" size="0.095 0.0405" quat="0.707107 0.707107 0 0" rgba="0.698039 0.698039 0.698039 1"/>
<!--                            <geom class="collision" type="mesh" rgba="0.698039 0.698039 0.698039 1" mesh="RF_FOOT_Link"/>-->
                        </body>
                    </body>
                </body>
            </body>

            <body name="LF_abad_link" pos="0.3154 0.05 0">
                <inertial pos="-1.38221e-06 0.0119998 -3.78509e-06" quat="-0.000589927 0.707109 -0.000527551 0.707104" mass="0.778654" diaginertia="0.00121131 0.000960298 0.00087971"/>
                <joint name="LF_HAA" pos="0 0 0" axis="1 0 0" range="-1.57 1.57" actuatorfrcrange="-40 40"/>
                <geom class="visual" type="mesh" density="0" rgba="0.698039 0.698039 0.698039 1" mesh="LF_ABAD_Link"/>
                <geom class="collision" size="0.04 0.0325" quat="0.707107 0 0.707107 0" type="cylinder" rgba="0.698039 0.698039 0.698039 1"/>
                <body name="LF_thigh_link" pos="0 0.1388 0">
                    <inertial pos="-0.00412085 -0.0352419 -0.029079" quat="0.875057 0.115204 -0.00185057 0.470105" mass="2.10667" diaginertia="0.0136968 0.013538 0.00268849"/>
                    <joint name="LF_HFE" pos="0 0 0" axis="0 1 0" range="-1.04 4.18" actuatorfrcrange="-40 40"/>
                    <geom class="visual" type="mesh" density="0" rgba="0.698039 0.698039 0.698039 1" mesh="LF_THIGH_Link"/>
                    <geom class="collision" size="0.048 0.0175" pos="0 -0.048 0" quat="0.707107 0.707107 0 0" type="cylinder" rgba="0.698039 0.698039 0.698039 1"/>
                    <geom class="collision" size="0.062 0.025" quat="0.707107 0.707107 0 0" type="cylinder" rgba="0.698039 0.698039 0.698039 1"/>
                    <geom class="collision" size="0.075 0.025 0.025" pos="-0.03 0 -0.15" quat="0.707107 0 0.707107 0" type="box" rgba="0.698039 0.698039 0.698039 1"/>
                    <body name="LF_shank_link" pos="0 0 -0.272">
                        <inertial pos="0.00690866 0.0384609 -0.310503" quat="0.84516 0.0943631 -0.0225429 0.525635" mass="1.26483" diaginertia="0.0162686 0.0158352 0.00130706"/>
                        <joint name="LF_KNEE" pos="0 0 0" axis="0 1 0" range="-2.69 -0.68" actuatorfrcrange="-100 100"/>
                        <geom class="visual" type="mesh" density="0" rgba="0.698039 0.698039 0.698039 1" mesh="LF_SHANK_Link"/>
                        <geom class="collision" size="0.09 0.0125 0.0125" pos="0.035 0 -0.13" quat="0.764842 0 0.644218 0" type="box" rgba="0.698039 0.698039 0.698039 1"/>
                        <geom class="collision" size="0.045 0.016 0.0175" pos="0.03 0 -0.27" quat="0.581683 0 0.813416 0" type="box" rgba="0.698039 0.698039 0.698039 1"/>
<!--                        <geom class="collision" type="mesh" rgba="0.698039 0.698039 0.698039 1" mesh="LF_SHANK_Link"/>-->
                        <body name="LF_FOOT_link" pos="0 0.0889282 -0.365367" quat="1 -3.81917e-05 -5.98325e-10 1.56664e-05">
                            <inertial pos="4.11893e-09 -0.016568 -6.73453e-10" quat="0.5 0.5 0.5 0.5" mass="0.750197" diaginertia="0.00508244 0.00268749 0.00268749"/>
                            <joint name="LF_WHEEL" pos="0 0 0" axis="0 1 0" range="-17453.3 17453.3" actuatorfrcrange="-40 40"/>
                            <geom class="visual" type="mesh" density="0" material="grey" mesh="LF_FOOT_Link"/>
                            <geom class="collision" type="cylinder" size="0.095 0.0405" quat="0.707107 0.707107 0 0" rgba="0.698039 0.698039 0.698039 1"/>
<!--                            <geom class="collision" type="mesh" rgba="0.698039 0.698039 0.698039 1" mesh="LF_FOOT_Link"/>-->
                        </body>
                    </body>
                </body>
            </body>

            <body name="RH_abad_link" pos="-0.3155 -0.05 0">
                <inertial pos="-2.03304e-06 -0.0119999 -3.78531e-06" quat="0.000595832 0.707104 0.000521638 0.707109" mass="0.778648" diaginertia="0.00121131 0.000960297 0.000879709"/>
                <joint name="RH_HAA" pos="0 0 0" axis="1 0 0" range="-1.57 1.57" actuatorfrcrange="-40 40"/>
                <geom class="visual" type="mesh" density="0" rgba="0.698039 0.698039 0.698039 1" mesh="RH_ABAD_Link"/>
                <geom class="collision" size="0.04 0.0325" quat="0.707107 0 0.707107 0" type="cylinder" rgba="0.698039 0.698039 0.698039 1"/>
                <body name="RH_thigh_link" pos="0 -0.1388 0">
                    <inertial pos="0.00412085 0.0352419 -0.0290789" quat="0.875062 -0.115203 0.00184915 0.470097" mass="2.10668" diaginertia="0.0136968 0.0135381 0.0026885"/>
                    <joint name="RH_HFE" pos="0 0 0" axis="0 1 0" range="-4.18 1.04" actuatorfrcrange="-40 40"/>
                    <geom class="visual" type="mesh" density="0" rgba="0.698039 0.698039 0.698039 1" mesh="RH_THIGH_Link"/>
                    <geom class="collision" size="0.048 0.0175" pos="0 0.048 0" quat="0.707107 0.707107 0 0" type="cylinder" rgba="0.698039 0.698039 0.698039 1"/>
                    <geom class="collision" size="0.062 0.025" quat="0.707107 0.707107 0 0" type="cylinder" rgba="0.698039 0.698039 0.698039 1"/>
                    <geom class="collision" size="0.075 0.025 0.025" pos="0.03 0 -0.15" quat="0.707107 0 -0.707107 0" type="box" rgba="0.698039 0.698039 0.698039 1"/>
                    <body name="RH_shank_link" pos="0 0 -0.272">
                        <inertial pos="-0.00690864 -0.0384609 -0.310502" quat="0.845161 -0.0943635 0.0225414 0.525633" mass="1.26483" diaginertia="0.0162686 0.0158352 0.00130705"/>
                        <joint name="RH_KNEE" pos="0 0 0" axis="0 1 0" range="0.68 2.69" actuatorfrcrange="-100 100"/>
                        <geom class="visual" type="mesh" density="0" rgba="0.698039 0.698039 0.698039 1" mesh="RH_SHANK_Link"/>
<!--                        <geom class="collision" type="mesh" rgba="0.698039 0.698039 0.698039 1" mesh="RH_SHANK_Link"/>-->
                        <geom class="collision" size="0.09 0.0125 0.0125" pos="-0.035 0 -0.13" quat="0.764842 0 -0.644218 0" type="box" rgba="0.698039 0.698039 0.698039 1"/>
                        <geom class="collision" size="0.045 0.016 0.0175" pos="-0.03 0 -0.27" quat="0.581683 0 -0.813416 0" type="box" rgba="0.698039 0.698039 0.698039 1"/>
                        <body name="RH_FOOT_link" pos="0 -0.0889282 -0.365367" quat="1 3.81917e-05 5.98325e-10 1.56664e-05">
                            <inertial pos="-4.11893e-09 0.016568 -6.73453e-10" quat="0.5 0.5 0.5 0.5" mass="0.750197" diaginertia="0.00508244 0.00268749 0.00268749"/>
                            <joint name="RH_WHEEL" pos="0 0 0" axis="0 1 0" range="-17453.3 17453.3" actuatorfrcrange="-40 40"/>
                            <geom class="visual" type="mesh" density="0" material="grey" mesh="RH_FOOT_Link"/>
                            <geom class="collision" type="cylinder" size="0.095 0.0405" quat="0.707107 0.707107 0 0" rgba="0.698039 0.698039 0.698039 1"/>
<!--                            <geom class="collision" type="mesh" rgba="0.698039 0.698039 0.698039 1" mesh="RH_FOOT_Link"/>-->
                        </body>
                    </body>
                </body>
            </body>

            <body name="LH_abad_link" pos="-0.3155 0.05 0">
                <inertial pos="-1.36846e-06 0.0119998 -3.78369e-06" quat="-0.000590709 0.707109 -0.000526824 0.707104" mass="0.778654" diaginertia="0.00121131 0.000960298 0.00087971"/>
                <joint name="LH_HAA" pos="0 0 0" axis="1 0 0" range="-1.57 1.57" actuatorfrcrange="-40 40"/>
                <geom class="visual" type="mesh" density="0" rgba="0.698039 0.698039 0.698039 1" mesh="LH_ABAD_Link"/>
                <geom class="collision" size="0.04 0.0325" quat="0.707107 0 0.707107 0" type="cylinder" rgba="0.698039 0.698039 0.698039 1"/>
                <body name="LH_thigh_link" pos="0 0.1388 0">
                    <inertial pos="0.0041208 -0.0352397 -0.029084" quat="0.469884 0.00183043 -0.11521 0.875175" mass="2.10685" diaginertia="0.0136982 0.0135394 0.00268877"/>
                    <joint name="LH_HFE" pos="0 0 0" axis="0 1 0" range="-4.18 1.04" actuatorfrcrange="-40 40"/>
                    <geom class="visual" type="mesh" density="0" rgba="0.698039 0.698039 0.698039 1" mesh="LH_THIGH_Link"/>
                    <geom class="collision" size="0.048 0.0175" pos="0 -0.048 0" quat="0.707107 0.707107 0 0" type="cylinder" rgba="0.698039 0.698039 0.698039 1"/>
                    <geom class="collision" size="0.062 0.025" quat="0.707107 0.707107 0 0" type="cylinder" rgba="0.698039 0.698039 0.698039 1"/>
                    <geom class="collision" size="0.075 0.025 0.025" pos="0.03 0 -0.15" quat="0.707107 0 -0.707107 0" type="box" rgba="0.698039 0.698039 0.698039 1"/>
                    <body name="LH_shank_link" pos="0 0 -0.272">
                        <inertial pos="-0.00690497 0.0384556 -0.310503" quat="0.525543 0.0225509 -0.0943693 0.845216" mass="1.26487" diaginertia="0.0162685 0.0158352 0.0013072"/>
                        <joint name="LH_KNEE" pos="0 0 0" axis="0 1 0" range="0.68 2.69" actuatorfrcrange="-100 100"/>
                        <geom class="visual" type="mesh" density="0" rgba="0.698039 0.698039 0.698039 1" mesh="LH_SHANK_Link"/>
<!--                        <geom class="collision" type="mesh" rgba="0.698039 0.698039 0.698039 1" mesh="LH_SHANK_Link"/>-->
                        <geom class="collision" size="0.09 0.0125 0.0125" pos="-0.035 0 -0.13" quat="0.764842 0 -0.644218 0" type="box" rgba="0.698039 0.698039 0.698039 1"/>
                        <geom class="collision" size="0.045 0.016 0.0175" pos="-0.03 0 -0.27" quat="0.581683 0 -0.813416 0" type="box" rgba="0.698039 0.698039 0.698039 1"/>
                        <body name="LH_FOOT_link" pos="0 0.0889282 -0.365367" quat="1 -3.81916e-05 5.98329e-10 -1.56665e-05">
                            <inertial pos="4.11892e-09 -0.016568 -6.73454e-10" quat="0.5 0.5 0.5 0.5" mass="0.750197" diaginertia="0.00508244 0.00268749 0.00268749"/>
                            <joint name="LH_WHEEL" pos="0 0 0" axis="0 1 0" range="-17453.3 17453.3" actuatorfrcrange="-40 40"/>
                            <geom class="visual" type="mesh" density="0" material="grey" mesh="LH_FOOT_Link"/>
                            <geom class="collision" type="cylinder" size="0.095 0.0405" quat="0.707107 0.707107 0 0" rgba="0.698039 0.698039 0.698039 1"/>
<!--                            <geom class="collision" type="mesh" rgba="0.698039 0.698039 0.698039 1" mesh="LH_FOOT_Link"/>-->
                        </body>
                    </body>
                </body>
            </body>
        </body>
    </worldbody>

    <actuator>
        <motor class="abad" name="FR_ABAD" joint="RF_HAA"/>
        <motor class="hip" name="FR_HIP" joint="RF_HFE"/>
        <motor class="knee" name="FR_KNEE" joint="RF_KNEE"/>

        <motor class="abad" name="FL_ABAD" joint="LF_HAA"/>
        <motor class="hip" name="FL_HIP" joint="LF_HFE"/>
        <motor class="knee" name="FL_KNEE" joint="LF_KNEE"/>

        <motor class="abad" name="RR_ABAD" joint="RH_HAA"/>
        <motor class="hip" name="RR_HIP" joint="RH_HFE"/>
        <motor class="knee" name="RR_KNEE" joint="RH_KNEE"/>

        <motor class="abad" name="RL_ABAD" joint="LH_HAA"/>
        <motor class="hip" name="RL_HIP" joint="LH_HFE"/>
        <motor class="knee" name="RL_KNEE" joint="LH_KNEE"/>

        <motor class="wheel" name="FR_WHEEL" joint="RF_WHEEL"/>
        <motor class="wheel" name="FL_WHEEL" joint="LF_WHEEL"/>
        <motor class="wheel" name="RR_WHEEL" joint="RH_WHEEL"/>
        <motor class="wheel" name="RL_WHEEL" joint="LH_WHEEL"/>
    </actuator>

    <sensor>
        <gyro name="body_gyro" site="imu"/>
        <framequat name="body_quat" objtype="site" objname="imu"/>
        <accelerometer name="body_acc" site="imu"/>
    </sensor>

    <keyframe>
        <key name="home"
             qpos="0 0 0.25
                   1 0 0 0
                   0.0 1.57086 -2.9  0.0
                   0.0 1.57086 -2.9 0.0
                   -0.0 -1.57086 2.9 0.0
                   0.0 -1.57086 2.9 0.0"/>
        <key name="default_pos"
             qpos="0 0 0.55
                   1 0 0 0
                   0.0 0.95 -1.6 0.0
                   0.0 0.95 -1.6 0.0
                   0.0 -0.95 1.6 0.0
                   0.0 -0.95 1.6 0.0"/>
    </keyframe>
</mujoco>
